Workbook
Name CYC_INGRESO: 'Burger-F7-F8'!$N$5:$N$66
Name F5_INGRESO: 'AFI-F5'!$N$5:$N$72
Name CYC_VENDEDOR: 'GB4'!$P$5:$P$34
Name F4_SALDO: 'AFI-F4'!$O$5:$O$72
Name BD_TABLA: Base_General!$B$3:$X$989
Name KAMADO_SALDO: #REF!
Name CYC_INGRESO: 'CyC-F11-F12'!$N$5:$N$66
Name CYC_SALDO: 'GN-Completo'!$O$5:$O$66
Name Online_INGRESO: ONLINE!$N$5:$N$204
Name F4_VENDEDOR: 'AFI-F4'!$P$5:$P$72
Name KAMADO_VENDEDOR: #REF!
Name CYC_SALDO: 'GB2'!$O$5:$O$34
Name MARINA_VENDEDOR: Corporativo!$P$5:$P$14
Name CYC_VENDEDOR: 'CyC-F11-F12'!$P$5:$P$66
Name F3_VENDEDOR: 'AFI-F3'!$P$5:$P$72
Name MARINA_VENDEDOR: 'Burger-F9-F10'!$P$5:$P$66
Name CYC_SALDO: 'GB4'!$O$5:$O$34
Name CYC_VENDEDOR: 'GB1'!$Q$5:$Q$34
Name F1_VENDEDOR: 'AFI-F1'!$P$5:$P$72
Name CYC_SALDO: 'CyC-F11-F12'!$O$5:$O$66
Name CYC_SALDO: 'GB3'!$O$5:$O$34
Name F2_VENDEDOR: 'AFI-F2'!$Q$5:$Q$72
Name BaseDatos: Base_General!$B$3:$X$928
Name Online_VENDEDOR: ONLINE!$P$5:$P$204
Name CYC_INGRESO: 'GB2'!$N$5:$N$34
Name CYC_SALDO: 'GB1'!$P$5:$P$34
Name F3_SALDO: 'AFI-F3'!$O$5:$O$72
Name F1_INGRESO: 'AFI-F1'!$N$5:$N$72
Name F5_VENDEDOR: 'AFI-F5'!$P$5:$P$72
Name F6_SALDO: 'AFI-F6'!$O$5:$O$72
Name F2_SALDO: 'AFI-F2'!$P$5:$P$72
Name F5_SALDO: 'AFI-F5'!$O$5:$O$72
Name F2_INGRESO: 'AFI-F2'!$N$5:$N$72
Name CYC_INGRESO: 'GB1'!$N$5:$N$34
Name F6_VENDEDOR: 'AFI-F6'!$P$5:$P$72
Name CUENTAS: VARIABLE!$B$4:$B$15
Name VENDEDOR: VARIABLE!$D$4:$D$15
Name KAMADO_INGRESO: #REF!
Name CYC_VENDEDOR: 'GB2'!$P$5:$P$34
Name MARINA_INGRESO: 'Burger-F9-F10'!$N$5:$N$66
Name CYC_VENDEDOR: 'GB3'!$P$5:$P$34
Name CYC_INGRESO: 'GB3'!$N$5:$N$34
Name CYC_INGRESO: 'GB4'!$N$5:$N$34
Name F4_INGRESO: 'AFI-F4'!$N$5:$N$72
Name SITUACION: VARIABLE!$F$4:$F$7
Name CYC_INGRESO: 'GN-Completo'!$N$5:$N$66
Name F1_SALDO: 'AFI-F1'!$O$5:$O$72
Name F3_INGRESO: 'AFI-F3'!$N$5:$N$72
Name F6_INGRESO: 'AFI-F6'!$N$5:$N$72
Name CYC_SALDO: 'Burger-F7-F8'!$O$5:$O$66
Name MARINA_SALDO: Corporativo!$O$5:$O$14
Name CYC_VENDEDOR: 'Burger-F7-F8'!$P$5:$P$66
Name TALLERES: VARIABLE!$H$4:$H$8
Name MARINA_INGRESO: Corporativo!$N$5:$N$14
Name CYC_VENDEDOR: 'GN-Completo'!$P$5:$P$66
Name MARINA_SALDO: 'Burger-F9-F10'!$O$5:$O$66

Sheet Base_General
B3: ID | C3: MES | D3: SEMANA | E3: DIA | F3: FECHA_dia | G3: PRODUCTO | H3: PROD FECHA | I3: FE_ REGISTRO | J3: DNI | K3: NOMBRES Y APELLIDOS | L3: EMAIL | M3: DISTRITO | N3: WSP | O3: F1 | P3: F2 | Q3: MONTO | R3: xCOBRAR | S3: ESTADO | T3: CUENTA | U3: INGRESO | V3: SALDO | W3: VENDEDOR | X3: TOTAL
B4: 1 | C4: =TEXT(I4,"Mmmm") -> diciembre | D4: =WEEKNUM(I4) -> 51 | E4: =TEXT(I4,"DDDD") -> miércoles | F4: =DAY(I4) -> 17 | G4: AFI | H4: ='AFI-F1'!$G$3 -> 45661 | I4: ='AFI-F1'!B5 -> 46008 | J4: ='AFI-F1'!C5 -> 72041694 | K4: ='AFI-F1'!D5 -> Sebastian Castillo | L4: ='AFI-F1'!E5 -> sebastiancm@outlook.com | M4: ='AFI-F1'!F5 -> BARRANCO | N4: ='AFI-F1'!G5 -> 998 690 869 | O4: ='AFI-F1'!H5 -> X | P4: ='AFI-F1'!I5 | ... X4: ='AFI-F1'!Q5 -> 250
B5: =B4+1 -> 2 | C5: =TEXT(I5,"Mmmm") -> diciembre | D5: =WEEKNUM(I5) -> 51 | E5: =TEXT(I5,"DDDD") -> sábado | F5: =DAY(I5) -> 20 | G5: AFI | H5: ='AFI-F1'!$G$3 -> 45661 | I5: ='AFI-F1'!B6 -> 46011 | J5: ='AFI-F1'!C6 -> 75931158 | K5: ='AFI-F1'!D6 -> Daniel Rojas Salas | L5: ='AFI-F1'!E6 -> juanchadrs@gmail.com | M5: ='AFI-F1'!F6 -> la victoria | N5: ='AFI-F1'!G6 | O5: ='AFI-F1'!H6 -> X | P5: ='AFI-F1'!I6 | ... X5: ='AFI-F1'!Q6 -> 190
B6: =B5+1 -> 3 | C6: =TEXT(I6,"Mmmm") -> diciembre | D6: =WEEKNUM(I6) -> 51 | E6: =TEXT(I6,"DDDD") -> sábado | F6: =DAY(I6) -> 20 | G6: AFI | H6: ='AFI-F1'!$G$3 -> 45661 | I6: ='AFI-F1'!B7 -> 46011 | J6: ='AFI-F1'!C7 -> 25631173 | K6: ='AFI-F1'!D7 -> Miriam Salas Guevara | L6: ='AFI-F1'!E7 -> elysalas2004@hotmail.com | M6: ='AFI-F1'!F7 -> villa el salvador | N6: ='AFI-F1'!G7 | O6: ='AFI-F1'!H7 -> X | P6: ='AFI-F1'!I7 | ... X6: ='AFI-F1'!Q7 -> 190
B7: =B6+1 -> 4 | C7: =TEXT(I7,"Mmmm") -> diciembre | D7: =WEEKNUM(I7) -> 52 | E7: =TEXT(I7,"DDDD") -> sábado | F7: =DAY(I7) -> 30 | G7: AFI | H7: ='AFI-F1'!$G$3 -> 45661 | I7: ='AFI-F1'!B8 | J7: ='AFI-F1'!C8 | K7: ='AFI-F1'!E8 | L7: ='AFI-F1'!E8 | M7: ='AFI-F1'!F8 | N7: ='AFI-F1'!G8 | O7: ='AFI-F1'!H8 | P7: ='AFI-F1'!I8 | Q7: ='AFI-F1'!J8 | R7: ='AFI-F1'!K8 | S7: ='AFI-F1'!L8 | ... X7: ='AFI-F1'!Q8 -> 0
B8: =B7+1 -> 5 | C8: =TEXT(I8,"Mmmm") -> noviembre | D8: =WEEKNUM(I8) -> 46 | E8: =TEXT(I8,"DDDD") -> domingo | F8: =DAY(I8) -> 9 | G8: AFI | H8: ='AFI-F1'!$G$3 -> 45661 | I8: ='AFI-F1'!B9 -> 45970 | J8: ='AFI-F1'!C9 -> 75728889 | K8: ='AFI-F1'!D9 -> Juan Carlos Vidal Molina | L8: ='AFI-F1'!E9 -> hellenleon7@gmail.com | M8: ='AFI-F1'!F9 -> CHACLACAYO | N8: ='AFI-F1'!G9 -> 989 356 823 | O8: ='AFI-F1'!H9 -> X | P8: ='AFI-F1'!I9 | ... X8: ='AFI-F1'!Q9 -> 220
B9: =B8+1 -> 6 | C9: =TEXT(I9,"Mmmm") -> diciembre | D9: =WEEKNUM(I9) -> 52 | E9: =TEXT(I9,"DDDD") -> viernes | F9: =DAY(I9) -> 26 | G9: AFI | H9: ='AFI-F1'!$G$3 -> 45661 | I9: ='AFI-F1'!B10 -> 46017 | J9: ='AFI-F1'!C10 -> 44000113 | K9: ='AFI-F1'!D10 -> CESAR KENNY YACARINI PEREYRA | L9: ='AFI-F1'!E10 -> ckyacariniman2@gmail.com | M9: ='AFI-F1'!F10 -> SJL | N9: ='AFI-F1'!G10 -> 947 169 905 | O9: ='AFI-F1'!H10 -> X | P9: ='AFI-F1'!I10 | ... X9: ='AFI-F1'!Q10 -> 190
B10: =B9+1 -> 7 | C10: =TEXT(I10,"Mmmm") -> diciembre | D10: =WEEKNUM(I10) -> 52 | E10: =TEXT(I10,"DDDD") -> viernes | F10: =DAY(I10) -> 26 | G10: AFI | H10: ='AFI-F1'!$G$3 -> 45661 | I10: ='AFI-F1'!B11 -> 46017 | J10: ='AFI-F1'!C11 -> 43619681 | K10: ='AFI-F1'!D11 -> Ronald elvis quispe gil | L10: ='AFI-F1'!E11 -> Reqg_672@hotmail.com | M10: ='AFI-F1'!F11 -> SJL | N10: ='AFI-F1'!G11 | O10: ='AFI-F1'!H11 -> X | P10: ='AFI-F1'!I11 | ... X10: ='AFI-F1'!Q11 -> 190
B11: =B10+1 -> 8 | C11: =TEXT(I11,"Mmmm") -> diciembre | D11: =WEEKNUM(I11) -> 52 | E11: =TEXT(I11,"DDDD") -> viernes | F11: =DAY(I11) -> 26 | G11: AFI | H11: ='AFI-F1'!$G$3 -> 45661 | I11: ='AFI-F1'!B12 -> 46017 | J11: ='AFI-F1'!C12 -> 43943113 | K11: ='AFI-F1'!D12 -> Flor de maria Guevara | L11: ='AFI-F1'!E12 -> Gerencia@imelin.com.pe | M11: ='AFI-F1'!F12 -> SJL | N11: ='AFI-F1'!G12 | O11: ='AFI-F1'!H12 -> X | P11: ='AFI-F1'!I12 | ... X11: ='AFI-F1'!Q12 -> 190
B12: =B11+1 -> 9 | C12: =TEXT(I12,"Mmmm") -> diciembre | D12: =WEEKNUM(I12) -> 53 | E12: =TEXT(I12,"DDDD") -> lunes | F12: =DAY(I12) -> 29 | G12: AFI | H12: ='AFI-F1'!$G$3 -> 45661 | I12: ='AFI-F1'!B13 -> 46020 | J12: ='AFI-F1'!C13 | K12: ='AFI-F1'!D13 -> Franco Nieto Ponce | L12: ='AFI-F1'!E13 | M12: ='AFI-F1'!F13 | N12: ='AFI-F1'!G13 | O12: ='AFI-F1'!H13 -> x | P12: ='AFI-F1'!I13 | ... X12: ='AFI-F1'!Q13 -> 190
B13: =B12+1 -> 10 | C13: =TEXT(I13,"Mmmm") -> diciembre | D13: =WEEKNUM(I13) -> 53 | E13: =TEXT(I13,"DDDD") -> lunes | F13: =DAY(I13) -> 29 | G13: AFI | H13: ='AFI-F1'!$G$3 -> 45661 | I13: ='AFI-F1'!B14 -> 46020 | J13: ='AFI-F1'!C14 | K13: ='AFI-F1'!D14 -> Luis Enrique Nieto Arauco | L13: ='AFI-F1'!E14 | M13: ='AFI-F1'!F14 | N13: ='AFI-F1'!G14 | O13: ='AFI-F1'!H14 -> x | P13: ='AFI-F1'!I14 | ... X13: ='AFI-F1'!Q14 -> 190
B14: =B13+1 -> 11 | C14: =TEXT(I14,"Mmmm") -> diciembre | D14: =WEEKNUM(I14) -> 53 | E14: =TEXT(I14,"DDDD") -> lunes | F14: =DAY(I14) -> 29 | G14: AFI | H14: ='AFI-F1'!$G$3 -> 45661 | I14: ='AFI-F1'!B15 -> 46020 | J14: ='AFI-F1'!C15 | K14: ='AFI-F1'!D15 -> Gladys Montes | L14: ='AFI-F1'!E15 | M14: ='AFI-F1'!F15 -> SJL | N14: ='AFI-F1'!G15 | O14: ='AFI-F1'!H15 -> x | P14: ='AFI-F1'!I15 | ... X14: ='AFI-F1'!Q15 -> 175
B15: =B14+1 -> 12 | C15: =TEXT(I15,"Mmmm") -> diciembre | D15: =WEEKNUM(I15) -> 53 | E15: =TEXT(I15,"DDDD") -> lunes | F15: =DAY(I15) -> 29 | G15: AFI | H15: ='AFI-F1'!$G$3 -> 45661 | I15: ='AFI-F1'!B16 -> 46020 | J15: ='AFI-F1'!C16 | K15: ='AFI-F1'!D16 -> Fernando Alfredo Auqui Cerron | L15: ='AFI-F1'!E16 | M15: ='AFI-F1'!F16 -> SJL | N15: ='AFI-F1'!G16 | O15: ='AFI-F1'!H16 -> x | P15: ='AFI-F1'!I16 | ... X15: ='AFI-F1'!Q16 -> 175
B16: =B15+1 -> 13 | C16: =TEXT(I16,"Mmmm") -> diciembre | D16: =WEEKNUM(I16) -> 53 | E16: =TEXT(I16,"DDDD") -> lunes | F16: =DAY(I16) -> 29 | G16: AFI | H16: ='AFI-F1'!$G$3 -> 45661 | I16: ='AFI-F1'!B17 -> 46020 | J16: ='AFI-F1'!C17 | K16: ='AFI-F1'!D17 -> Gianfranco Auqui Guerrero | L16: ='AFI-F1'!E17 | M16: ='AFI-F1'!F17 -> SJL | N16: ='AFI-F1'!G17 | O16: ='AFI-F1'!H17 -> x | P16: ='AFI-F1'!I17 | ... X16: ='AFI-F1'!Q17 -> 175
B17: =B16+1 -> 14 | C17: =TEXT(I17,"Mmmm") -> diciembre | D17: =WEEKNUM(I17) -> 53 | E17: =TEXT(I17,"DDDD") -> lunes | F17: =DAY(I17) -> 29 | G17: AFI | H17: ='AFI-F1'!$G$3 -> 45661 | I17: ='AFI-F1'!B18 -> 46020 | J17: ='AFI-F1'!C18 | K17: ='AFI-F1'!D18 -> Germán Auqui Cerrón | L17: ='AFI-F1'!E18 | M17: ='AFI-F1'!F18 -> SJL | N17: ='AFI-F1'!G18 | O17: ='AFI-F1'!H18 -> x | P17: ='AFI-F1'!I18 | ... X17: ='AFI-F1'!Q18 -> 175
B18: =B17+1 -> 15 | C18: =TEXT(I18,"Mmmm") -> diciembre | D18: =WEEKNUM(I18) -> 53 | E18: =TEXT(I18,"DDDD") -> martes | F18: =DAY(I18) -> 30 | G18: AFI | H18: ='AFI-F1'!$G$3 -> 45661 | I18: ='AFI-F1'!B19 -> 46021 | J18: ='AFI-F1'!C19 -> 49035262 | K18: ='AFI-F1'!D19 -> Rafael Antony Urbina Peña | L18: ='AFI-F1'!E19 -> rafaelurbi24@gmail.com | M18: ='AFI-F1'!F19 -> LOS OLIVOS | N18: ='AFI-F1'!G19 | O18: ='AFI-F1'!H19 -> X | P18: ='AFI-F1'!I19 | ... X18: ='AFI-F1'!Q19 -> 350
B19: =B18+1 -> 16 | C19: =TEXT(I19,"Mmmm") -> diciembre | D19: =WEEKNUM(I19) -> 53 | E19: =TEXT(I19,"DDDD") -> miércoles | F19: =DAY(I19) -> 31 | G19: AFI | H19: ='AFI-F1'!$G$3 -> 45661 | I19: ='AFI-F1'!B20 -> 46022 | J19: ='AFI-F1'!C20 -> 71486933 | K19: ='AFI-F1'!D20 -> Roberto Benites Aguilar | L19: ='AFI-F1'!E20 -> benites.07@hotmail.com | M19: ='AFI-F1'!F20 | N19: ='AFI-F1'!G20 | O19: ='AFI-F1'!H20 -> x | P19: ='AFI-F1'!I20 | ... X19: ='AFI-F1'!Q20 -> 220
... B71: =B70+1 -> 68 | C71: =TEXT(I71,"Mmmm") -> diciembre | D71: =WEEKNUM(I71) -> 52 | E71: =TEXT(I71,"DDDD") -> sábado | F71: =DAY(I71) -> 30 | G71: AFI | H71: ='AFI-F1'!$G$3 -> 45661 | I71: ='AFI-F1'!B72 | J71: ='AFI-F1'!C72 | K71: ='AFI-F1'!D72 | L71: ='AFI-F1'!E72 | M71: ='AFI-F1'!F72 | N71: ='AFI-F1'!G72 | O71: ='AFI-F1'!H72 | P71: ='AFI-F1'!I72 | ... X71: ='AFI-F1'!Q72 -> 0
B72: 1 | C72: =TEXT(I72,"Mmmm") -> diciembre | D72: =WEEKNUM(I72) -> 49 | E72: =TEXT(I72,"DDDD") -> martes | F72: =DAY(I72) -> 2 | G72: AFI | H72: ='AFI-F2'!$G$3 -> 45668 | I72: ='AFI-F2'!B5 -> 45993 | J72: ='AFI-F2'!C5 -> 47078798 | K72: ='AFI-F2'!D5 -> Anthony Molina Heredia | L72: ='AFI-F2'!E5 -> anthony.molinah@gmail.com | M72: ='AFI-F2'!F5 -> VMT | N72: ='AFI-F2'!G5 -> 968 358 245 | O72: ='AFI-F2'!H5 | P72: ='AFI-F2'!I5 -> X | ... U72: ='AFI-F2'!N5 -> 220 | V72: ='AFI-F2'!P5 | W72: ='AFI-F2'!Q5 -> Yadhira | X72: ='AFI-F2'!R5 -> 220
B73: =B72+1 -> 2 | C73: =TEXT(I73,"Mmmm") -> diciembre | D73: =WEEKNUM(I73) -> 51 | E73: =TEXT(I73,"DDDD") -> miércoles | F73: =DAY(I73) -> 17 | G73: AFI | H73: ='AFI-F2'!$G$3 -> 45668 | I73: ='AFI-F2'!B6 -> 46008 | J73: ='AFI-F2'!C6 -> 44681923 | K73: ='AFI-F2'!D6 -> Rodrigo Bustamante Moquillaza | L73: ='AFI-F2'!E6 -> Roodj88@gmail.com | M73: ='AFI-F2'!F6 -> SURQUILLO | N73: ='AFI-F2'!G6 -> 995 586 556 | O73: ='AFI-F2'!H6 | P73: ='AFI-F2'!I6 -> X | ... U73: ='AFI-F2'!N6 -> 200 | V73: ='AFI-F2'!P6 | W73: ='AFI-F2'!Q6 -> Yadhira | X73: ='AFI-F2'!R6 -> 355
B74: =B73+1 -> 3 | C74: =TEXT(I74,"Mmmm") -> diciembre | D74: =WEEKNUM(I74) -> 51 | E74: =TEXT(I74,"DDDD") -> miércoles | F74: =DAY(I74) -> 17 | G74: AFI | H74: ='AFI-F2'!$G$3 -> 45668 | I74: ='AFI-F2'!B7 -> 46008 | J74: ='AFI-F2'!C7 | K74: ='AFI-F2'!D7 -> Philip Wenter Bustamante | L74: ='AFI-F2'!E7 -> Roodj88@gmail.com | M74: ='AFI-F2'!F7 -> SURQUILLO | N74: ='AFI-F2'!G7 -> 995 586 556 | O74: ='AFI-F2'!H7 | P74: ='AFI-F2'!I7 -> X | ... U74: ='AFI-F2'!N7 -> 200 | V74: ='AFI-F2'!P7 | W74: ='AFI-F2'!Q7 -> Yadhira | X74: ='AFI-F2'!R7 -> 355
B75: =B74+1 -> 4 | C75: =TEXT(I75,"Mmmm") -> diciembre | D75: =WEEKNUM(I75) -> 51 | E75: =TEXT(I75,"DDDD") -> miércoles | F75: =DAY(I75) -> 17 | G75: AFI | H75: ='AFI-F2'!$G$3 -> 45668 | I75: ='AFI-F2'!B8 -> 46008 | J75: ='AFI-F2'!C8 -> 72495808 | K75: ='AFI-F2'!D8 -> Sebastian Matias Prada Fernandez | L75: ='AFI-F2'!E8 -> Matias_pf_21@hotmail.com | M75: ='AFI-F2'!F8 -> LA VICTORIA | N75: ='AFI-F2'!G8 -> 954 532 968 | O75: ='AFI-F2'!H8 -> X | P75: ='AFI-F2'!I8 -> X | ... U75: ='AFI-F2'!N8 -> 190 | V75: ='AFI-F2'!P8 | W75: ='AFI-F2'!Q8 -> Yadhira | X75: ='AFI-F2'!R8 -> 380
B76: =B75+1 -> 5 | C76: =TEXT(I76,"Mmmm") -> diciembre | D76: =WEEKNUM(I76) -> 51 | E76: =TEXT(I76,"DDDD") -> miércoles | F76: =DAY(I76) -> 17 | G76: AFI | H76: ='AFI-F2'!$G$3 -> 45668 | I76: ='AFI-F2'!B9 -> 46008 | J76: ='AFI-F2'!C9 -> 09594474 | K76: ='AFI-F2'!D9 -> Jorge Fernandez Huaman | L76: ='AFI-F2'!E9 -> Matias_pf_21@hotmail.com | M76: ='AFI-F2'!F9 -> LA VICTORIA | N76: ='AFI-F2'!G9 -> 954 532 968 | O76: ='AFI-F2'!H9 -> X | P76: ='AFI-F2'!I9 | ... U76: ='AFI-F2'!N9 -> 95 | V76: ='AFI-F2'!P9 | W76: ='AFI-F2'!Q9 -> Yadhira | X76: ='AFI-F2'!R9 -> 190
B77: =B76+1 -> 6 | C77: =TEXT(I77,"Mmmm") -> diciembre | D77: =WEEKNUM(I77) -> 52 | E77: =TEXT(I77,"DDDD") -> martes | F77: =DAY(I77) -> 23 | G77: AFI | H77: ='AFI-F2'!$G$3 -> 45668 | I77: ='AFI-F2'!B10 -> 46014 | J77: ='AFI-F2'!C10 -> 44889118 | K77: ='AFI-F2'!D10 -> Miguel Ángel Requiz Alanís | L77: ='AFI-F2'!E10 -> Miguel.requiz10@gmail.com | M77: ='AFI-F2'!F10 -> SJL | N77: ='AFI-F2'!G10 -> 975 575 476 | O77: ='AFI-F2'!H10 -> X | P77: ='AFI-F2'!I10 -> X | ... U77: ='AFI-F2'!N10 -> 360 | V77: ='AFI-F2'!P10 | W77: ='AFI-F2'!Q10 -> Yadhira | X77: ='AFI-F2'!R10 -> 360
B78: =B77+1 -> 7 | C78: =TEXT(I78,"Mmmm") -> diciembre | D78: =WEEKNUM(I78) -> 52 | E78: =TEXT(I78,"DDDD") -> martes | F78: =DAY(I78) -> 23 | G78: AFI | H78: ='AFI-F2'!$G$3 -> 45668 | I78: ='AFI-F2'!B11 -> 46014 | J78: ='AFI-F2'!C11 -> 43045566 | K78: ='AFI-F2'!D11 -> Carlos Miguel Olivares Pérez | L78: ='AFI-F2'!E11 -> Miguel.requiz10@gmail.com | M78: ='AFI-F2'!F11 -> CHICLAYO | N78: ='AFI-F2'!G11 -> 975 575 476 | O78: ='AFI-F2'!H11 -> X | P78: ='AFI-F2'!I11 -> X | ... U78: ='AFI-F2'!N11 -> 360 | V78: ='AFI-F2'!P11 | W78: ='AFI-F2'!Q11 -> Yadhira | X78: ='AFI-F2'!R11 -> 360
B79: =B78+1 -> 8 | C79: =TEXT(I79,"Mmmm") -> diciembre | D79: =WEEKNUM(I79) -> 51 | E79: =TEXT(I79,"DDDD") -> sábado | F79: =DAY(I79) -> 20 | G79: AFI | H79: ='AFI-F2'!$G$3 -> 45668 | I79: ='AFI-F2'!B12 -> 46011 | J79: ='AFI-F2'!C12 | K79: ='AFI-F2'!D12 -> Aldo Augusto Di liberto Roldán | L79: ='AFI-F2'!E12 -> aldodilibertoroldan@gmail.com | M79: ='AFI-F2'!F12 -> CHORRILLOS | N79: ='AFI-F2'!G12 -> 991385736 | O79: ='AFI-F2'!H12 -> X | P79: ='AFI-F2'!I12 | ... U79: ='AFI-F2'!N12 -> 95 | V79: ='AFI-F2'!P12 | W79: ='AFI-F2'!Q12 -> Yadhira | X79: ='AFI-F2'!R12 -> 190
B80: =B79+1 -> 9 | C80: =TEXT(I80,"Mmmm") -> diciembre | D80: =WEEKNUM(I80) -> 51 | E80: =TEXT(I80,"DDDD") -> sábado | F80: =DAY(I80) -> 20 | G80: AFI | H80: ='AFI-F2'!$G$3 -> 45668 | I80: ='AFI-F2'!B13 -> 46011 | J80: ='AFI-F2'!C13 | K80: ='AFI-F2'!D13 -> Yames Vicente di liberto Roldán | L80: ='AFI-F2'!E13 -> aldodilibertoroldan@gmail.com | M80: ='AFI-F2'!F13 -> CHORRILLOS | N80: ='AFI-F2'!G13 -> 991385736 | O80: ='AFI-F2'!H13 -> X | P80: ='AFI-F2'!I13 | ... U80: ='AFI-F2'!N13 -> 95 | V80: ='AFI-F2'!P13 | W80: ='AFI-F2'!Q13 -> Yadhira | X80: ='AFI-F2'!R13 -> 190
B81: =B80+1 -> 10 | C81: =TEXT(I81,"Mmmm") -> diciembre | D81: =WEEKNUM(I81) -> 53 | E81: =TEXT(I81,"DDDD") -> miércoles | F81: =DAY(I81) -> 30 | G81: AFI | H81: ='AFI-F2'!$G$3 -> 45668 | I81: ='AFI-F2'!B14 -> 46386 | J81: ='AFI-F2'!C14 -> 72616360 | K81: ='AFI-F2'!D14 -> Enrique Raynor La Torre Alarcón | L81: ='AFI-F2'!E14 -> enriquelta169@gmail.com | M81: ='AFI-F2'!F14 -> SAN BORJA | N81: ='AFI-F2'!G14 -> 966 922 334 | O81: ='AFI-F2'!H14 -> X | P81: ='AFI-F2'!I14 -> X | ... U81: ='AFI-F2'!N14 -> 380 | V81: ='AFI-F2'!P14 | W81: ='AFI-F2'!Q14 -> Greici | X81: ='AFI-F2'!R14 -> 380
B82: =B81+1 -> 11 | C82: =TEXT(I82,"Mmmm") -> diciembre | D82: =WEEKNUM(I82) -> 53 | E82: =TEXT(I82,"DDDD") -> martes | F82: =DAY(I82) -> 30 | G82: AFI | H82: ='AFI-F2'!$G$3 -> 45668 | I82: ='AFI-F2'!B15 -> 46021 | J82: ='AFI-F2'!C15 -> 49035262 | K82: ='AFI-F2'!D15 -> Rafael Antony Urbina Peña | L82: ='AFI-F2'!E15 -> rafaelurbi24@gmail.com | M82: ='AFI-F2'!F15 -> LOS OLIVOS | N82: ='AFI-F2'!G15 -> 927 235 029 | O82: ='AFI-F2'!H15 | P82: ='AFI-F2'!I15 -> X | ... U82: ='AFI-F2'!N15 -> 0 | V82: ='AFI-F2'!P15 | W82: ='AFI-F2'!Q15 -> Yadhira | X82: ='AFI-F2'!R15 -> 0
B83: =B82+1 -> 12 | C83: =TEXT(I83,"Mmmm") -> diciembre | D83: =WEEKNUM(I83) -> 53 | E83: =TEXT(I83,"DDDD") -> martes | F83: =DAY(I83) -> 30 | G83: AFI | H83: ='AFI-F2'!$G$3 -> 45668 | I83: ='AFI-F2'!B16 -> 46021 | J83: ='AFI-F2'!C16 -> 49032421 | K83: ='AFI-F2'!D16 -> Pierre Neyra | L83: ='AFI-F2'!E16 -> pierre.neyrape@gmail.com | M83: ='AFI-F2'!F16 -> MIRAFLORES | N83: ='AFI-F2'!G16 -> 954 134 851 | O83: ='AFI-F2'!H16 -> X | P83: ='AFI-F2'!I16 | ... U83: ='AFI-F2'!N16 -> 181.58 | V83: ='AFI-F2'!P16 | W83: ='AFI-F2'!Q16 -> Yadhira | X83: ='AFI-F2'!R16 -> 181.58
B84: =B83+1 -> 13 | C84: =TEXT(I84,"Mmmm") -> diciembre | D84: =WEEKNUM(I84) -> 53 | E84: =TEXT(I84,"DDDD") -> martes | F84: =DAY(I84) -> 30 | G84: AFI | H84: ='AFI-F2'!$G$3 -> 45668 | I84: ='AFI-F2'!B17 -> 46021 | J84: ='AFI-F2'!C17 -> 73185937 | K84: ='AFI-F2'!D17 -> Marieta Calderon | L84: ='AFI-F2'!E17 -> marietacristina@hotmail.com | M84: ='AFI-F2'!F17 -> MIRAFLORES | N84: ='AFI-F2'!G17 -> 954 134 851 | O84: ='AFI-F2'!H17 -> X | P84: ='AFI-F2'!I17 | ... U84: ='AFI-F2'!N17 -> 181.58 | V84: ='AFI-F2'!P17 | W84: ='AFI-F2'!Q17 -> Yadhira | X84: ='AFI-F2'!R17 -> 181.58
... B139: =B138+1 -> 68 | C139: =TEXT(I139,"Mmmm") -> diciembre | D139: =WEEKNUM(I139) -> 52 | E139: =TEXT(I139,"DDDD") -> sábado | F139: =DAY(I139) -> 30 | G139: AFI | H139: ='AFI-F2'!$G$3 -> 45668 | I139: ='AFI-F2'!B72 | J139: ='AFI-F2'!C72 | K139: ='AFI-F2'!D72 | L139: ='AFI-F2'!E72 | M139: ='AFI-F2'!F72 | N139: ='AFI-F2'!G72 | O139: ='AFI-F2'!H72 | P139: ='AFI-F2'!I72 | ... U139: ='AFI-F2'!N72 | V139: ='AFI-F2'!P72 | W139: ='AFI-F2'!Q72 | X139: ='AFI-F2'!R72 -> 0
B140: 1 | C140: =TEXT(I140,"Mmmm") -> diciembre | D140: =WEEKNUM(I140) -> 52 | E140: =TEXT(I140,"DDDD") -> martes | F140: =DAY(I140) -> 23 | G140: AFI | H140: ='AFI-F3'!$G$3 -> 45674 | I140: ='AFI-F3'!B5 -> 46014 | J140: ='AFI-F3'!C5 -> 41864072 | K140: ='AFI-F3'!D5 -> Alan Paul Otiniano Azahuanche | L140: ='AFI-F3'!E5 -> apoa315@hotmail.com | M140: ='AFI-F3'!F5 -> SURCO | N140: ='AFI-F3'!G5 -> 949 271 885 | O140: ='AFI-F3'!H5 -> X | P140: ='AFI-F3'!I5 | ... X140: ='AFI-F3'!Q5 -> 220
B141: =B140+1 -> 2 | C141: =TEXT(I141,"Mmmm") -> diciembre | D141: =WEEKNUM(I141) -> 52 | E141: =TEXT(I141,"DDDD") -> martes | F141: =DAY(I141) -> 23 | G141: AFI | H141: ='AFI-F3'!$G$3 -> 45674 | I141: ='AFI-F3'!B6 -> 46014 | J141: ='AFI-F3'!C6 -> 09954438 | K141: ='AFI-F3'!D6 -> Walter Peralta | L141: ='AFI-F3'!E6 -> Carolina.velosa@icloud.com | M141: ='AFI-F3'!F6 -> SAN BORJA | N141: ='AFI-F3'!G6 -> 987 737 748 | O141: ='AFI-F3'!H6 | P141: ='AFI-F3'!I6 -> X | ... X141: ='AFI-F3'!Q6 -> 220
B142: =B141+1 -> 3 | C142: =TEXT(I142,"Mmmm") -> diciembre | D142: =WEEKNUM(I142) -> 51 | E142: =TEXT(I142,"DDDD") -> jueves | F142: =DAY(I142) -> 18 | G142: AFI | H142: ='AFI-F3'!$G$3 -> 45674 | I142: ='AFI-F3'!B7 -> 46009 | J142: ='AFI-F3'!C7 -> 46649174 | K142: ='AFI-F3'!D7 -> Jonathan Marrou | L142: ='AFI-F3'!E7 -> Jonathan.marrou@gmail.com | M142: ='AFI-F3'!F7 -> SURCO | N142: ='AFI-F3'!G7 -> FB | O142: ='AFI-F3'!H7 | P142: ='AFI-F3'!I7 -> X | ... X142: ='AFI-F3'!Q7 -> 190
B143: =B142+1 -> 4 | C143: =TEXT(I143,"Mmmm") -> diciembre | D143: =WEEKNUM(I143) -> 51 | E143: =TEXT(I143,"DDDD") -> jueves | F143: =DAY(I143) -> 18 | G143: AFI | H143: ='AFI-F3'!$G$3 -> 45674 | I143: ='AFI-F3'!B8 -> 46009 | J143: ='AFI-F3'!C8 -> 10303242 | K143: ='AFI-F3'!D8 -> Ricardo Marrou | L143: ='AFI-F3'!E8 -> Ricardo.jonico@gmail.com | M143: ='AFI-F3'!F8 -> SURCO | N143: ='AFI-F3'!G8 -> FB | O143: ='AFI-F3'!H8 | P143: ='AFI-F3'!I8 -> X | ... X143: ='AFI-F3'!Q8 -> 190
B144: =B143+1 -> 5 | C144: =TEXT(I144,"Mmmm") -> diciembre | D144: =WEEKNUM(I144) -> 52 | E144: =TEXT(I144,"DDDD") -> martes | F144: =DAY(I144) -> 23 | G144: AFI | H144: ='AFI-F3'!$G$3 -> 45674 | I144: ='AFI-F3'!B9 -> 46014 | J144: ='AFI-F3'!C9 -> 44273674 | K144: ='AFI-F3'!D9 -> Ivan Salsavilca Faustino | L144: ='AFI-F3'!E9 -> ivansalsavilca@gmail.com | M144: ='AFI-F3'!F9 | N144: ='AFI-F3'!G9 | O144: ='AFI-F3'!H9 -> x | P144: ='AFI-F3'!I9 -> x | ... X144: ='AFI-F3'!Q9 -> 380
B145: =B144+1 -> 6 | C145: =TEXT(I145,"Mmmm") -> enero | D145: =WEEKNUM(I145) -> 1 | E145: =TEXT(I145,"DDDD") -> viernes | F145: =DAY(I145) -> 2 | G145: AFI | H145: ='AFI-F3'!$G$3 -> 45674 | I145: ='AFI-F3'!B10 -> 46024 | J145: ='AFI-F3'!C10 -> 77059170 | K145: ='AFI-F3'!D10 -> Nicolas Gámez | L145: ='AFI-F3'!E10 -> Nicogamez1008@gmail.com | M145: ='AFI-F3'!F10 -> Chorrillos | N145: ='AFI-F3'!G10 -> 924 714 156 | O145: ='AFI-F3'!H10 -> X | P145: ='AFI-F3'!I10 -> x | ... X145: ='AFI-F3'!Q10 -> 380
B146: =B145+1 -> 7 | C146: =TEXT(I146,"Mmmm") -> enero | D146: =WEEKNUM(I146) -> 2 | E146: =TEXT(I146,"DDDD") -> lunes | F146: =DAY(I146) -> 5 | G146: AFI | H146: ='AFI-F3'!$G$3 -> 45674 | I146: ='AFI-F3'!B11 -> 46027 | J146: ='AFI-F3'!C11 -> 42126105 | K146: ='AFI-F3'!D11 -> Manuel Buendia | L146: ='AFI-F3'!E11 -> Mbuendia4@gmail.com | M146: ='AFI-F3'!F11 -> CHACLACAYO | N146: ='AFI-F3'!G11 -> 961 082 768 | O146: ='AFI-F3'!H11 -> X | P146: ='AFI-F3'!I11 -> X | ... X146: ='AFI-F3'!Q11 -> 350
B147: =B146+1 -> 8 | C147: =TEXT(I147,"Mmmm") -> enero | D147: =WEEKNUM(I147) -> 2 | E147: =TEXT(I147,"DDDD") -> lunes | F147: =DAY(I147) -> 5 | G147: AFI | H147: ='AFI-F3'!$G$3 -> 45674 | I147: ='AFI-F3'!B12 -> 46027 | J147: ='AFI-F3'!C12 -> 41758472 | K147: ='AFI-F3'!D12 -> Liselle Prieto | L147: ='AFI-F3'!E12 -> Lisibuendia28@gmail.com | M147: ='AFI-F3'!F12 -> CHACLACAYO | N147: ='AFI-F3'!G12 -> 961 082 768 | O147: ='AFI-F3'!H12 -> X | P147: ='AFI-F3'!I12 -> X | ... X147: ='AFI-F3'!Q12 -> 350
...

Sheet TD
B2: 1 TD - VENTA ACTUAL POR VENDEDOR GENERAL
B19: 2 TD - VENTA ACTUAL POR PRODUCTO GENERAL
B35: 3 TD - RESUMEN DE VENTA ACTUAL POR PRODUCTO | F35: 4 TD - RESUMEN DE VENTA ACTUAL POR VENDEDOR
B48: 5 TD - VENTA SEMANAL PRODUCTOS
B63: 6 TD - VENTA SEMANAL ASESOR

Sheet AFI-F1
A1: -
A2: CONTROL DE REGISTRO PARTICIPANTES
A3: PARRILLERO AFICIONADO | G3: 45661
A4: ID | B4: FE_ REGISTRO | C4: DNI | D4: NOMBRES Y APELLIDOS | E4: EMAIL | F4: DISTRITO | G4: WSP | H4: BB1 | I4: BB2 | J4: MONTO | K4: xCOBRAR | L4: ESTADO | M4: CUENTA | N4: INGRESO | O4: SALDO | P4: VENDEDOR | Q4: TOTAL | R4: OBSERVACION
A5: 1 | B5: 46008 | C5: 72041694 | D5: Sebastian Castillo | E5: sebastiancm@outlook.com | F5: BARRANCO | G5: 998 690 869 | H5: X | J5: 250 | L5: PAGO | M5: YAPE JL | N5: 250 | P5: Yadhira | Q5: =N5+O5 -> 250
A6: =A5+1 -> 2 | B6: 46011 | C6: 75931158 | D6: Daniel Rojas Salas | E6: juanchadrs@gmail.com | F6: la victoria | H6: X | J6: 190 | L6: PAGO | M6: YAPE JL | N6: 190 | P6: Greici | Q6: =N6+O6 -> 190
A7: =A6+1 -> 3 | B7: 46011 | C7: 25631173 | D7: Miriam Salas Guevara | E7: elysalas2004@hotmail.com | F7: villa el salvador | H7: X | J7: 190 | L7: PAGO | M7: YAPE JL | N7: 190 | P7: Greici | Q7: =N7+O7 -> 190
A8: =A7+1 -> 4 | Q8: =N8+O8 -> 0 | R8: paso para 11/01
A9: =A8+1 -> 5 | B9: 45970 | C9: 75728889 | D9: Juan Carlos Vidal Molina | E9: hellenleon7@gmail.com | F9: CHACLACAYO | G9: 989 356 823 | H9: X | J9: 110 | K9: 110 | L9: COBR | M9: YAPE JL | N9: 110 | O9: 110 | P9: Yadhira | Q9: =N9+O9 -> 220
A10: =A9+1 -> 6 | B10: 46017 | C10: 44000113 | D10: CESAR KENNY YACARINI PEREYRA | E10: ckyacariniman2@gmail.com | F10: SJL | G10: 947 169 905 | H10: X | J10: 95 | K10: 95 | L10: COBR | M10: PLIN JL | N10: 95 | O10: 95 | P10: Greici | Q10: =N10+O10 -> 190
A11: =A10+1 -> 7 | B11: 46017 | C11: 43619681 | D11: Ronald elvis quispe gil | E11: Reqg_672@hotmail.com | F11: SJL | H11: X | J11: 95 | K11: 95 | L11: COBR | M11: PLIN JL | N11: 95 | O11: 95 | P11: Greici | Q11: =N11+O11 -> 190
A12: =A11+1 -> 8 | B12: 46017 | C12: 43943113 | D12: Flor de maria Guevara | E12: Gerencia@imelin.com.pe | F12: SJL | H12: X | J12: 95 | K12: 95 | L12: COBR | M12: PLIN JL | N12: 95 | O12: 95 | P12: Greici | Q12: =N12+O12 -> 190
A13: =A12+1 -> 9 | B13: 46020 | D13: Franco Nieto Ponce | H13: x | J13: 190 | L13: PAGO | M13: PLIN JL | N13: 190 | P13: Katherine | Q13: =N13+O13 -> 190
A14: =A13+1 -> 10 | B14: 46020 | D14: Luis Enrique Nieto Arauco | H14: x | J14: 190 | L14: PAGO | M14: PLIN JL | N14: 190 | P14: Katherine | Q14: =N14+O14 -> 190
A15: =A14+1 -> 11 | B15: 46020 | D15: Gladys Montes | F15: SJL | H15: x | J15: 50 | K15: 125 | L15: COBR | M15: PLIN JL | N15: 50 | O15: 125 | P15: Katherine | Q15: =N15+O15 -> 175
A16: =A15+1 -> 12 | B16: 46020 | D16: Fernando Alfredo Auqui Cerron | F16: SJL | H16: x | J16: 50 | K16: 125 | L16: COBR | M16: PLIN JL | N16: 50 | O16: 125 | P16: Katherine | Q16: =N16+O16 -> 175
A17: =A16+1 -> 13 | B17: 46020 | D17: Gianfranco Auqui Guerrero | F17: SJL | H17: x | J17: 50 | K17: 125 | L17: COBR | M17: PLIN JL | N17: 50 | O17: 125 | P17: Katherine | Q17: =N17+O17 -> 175
A18: =A17+1 -> 14 | B18: 46020 | D18: Germán Auqui Cerrón | F18: SJL | H18: x | J18: 50 | K18: 125 | L18: COBR | M18: PLIN JL | N18: 50 | O18: 125 | P18: Katherine | Q18: =N18+O18 -> 175
A19: =A18+1 -> 15 | B19: 46021 | C19: 49035262 | D19: Rafael Antony Urbina Peña | E19: rafaelurbi24@gmail.com | F19: LOS OLIVOS | H19: X | J19: 350 | L19: PAGO | M19: YAPE JL | N19: 350 | P19: Yadhira | Q19: =N19+O19 -> 350
A20: =A19+1 -> 16 | B20: 46022 | C20: 71486933 | D20: Roberto Benites Aguilar | E20: benites.07@hotmail.com | H20: x | J20: 220 | L20: PAGO | M20: YAPE JL | N20: 220 | P20: Katherine | Q20: =N20+O20 -> 220
A21: =A20+1 -> 17 | B21: 46022 | C21: 46910475 | D21: Ernesto De La Cruz | E21: ernesto199124@hotmail.com | F21: Chosica | H21: x | J21: 190 | L21: PAGO | M21: YAPE JL | N21: 190 | P21: Katherine | Q21: =N21+O21 -> 190
A22: =A21+1 -> 18 | B22: 46022 | D22: Hugo De La Cruz | F22: Chosica | H22: x | J22: 100 | L22: PAGO | M22: YAPE JL | N22: 100 | P22: Katherine | Q22: =N22+O22 -> 100
A23: =A22+1 -> 19 | B23: 46024 | C23: 40677695 | D23: Antonio Lora | E23: antoniolorac@gmail.com | F23: SURCO | H23: X | J23: 190 | L23: PAGO | M23: PLIN JL | N23: 190 | P23: Yadhira | Q23: =N23+O23 -> 190
A24: =A23+1 -> 20 | B24: 46024 | C24: 08553072 | D24: Luis Lora Reyes | E24: antoniolorac@gmail.com | F24: SURCO | H24: X | J24: 190 | L24: PAGO | M24: PLIN JL | N24: 190 | P24: Yadhira | Q24: =N24+O24 -> 190
A25: =A24+1 -> 21 | B25: 46024 | C25: 44041233 | D25: Rosa Juana Mogrovejo Sihue | E25: msk.rosa@gmail.com | F25: San Juan de Lurigancho | G25: 960 142 095 | H25: x | J25: 95 | K25: 95 | L25: COBR | M25: PLIN JL | N25: 95 | O25: 95 | P25: Sofia | Q25: =N25+O25 -> 190
A26: =A25+1 -> 22 | B26: 46025 | C26: 09312996 | D26: Hernán Vidal Ulloa | E26: havu20@gmail.com | F26: La Molina | G26: 965 007 792 | H26: x | J26: 190 | L26: PAGO | M26: YAPE JL | N26: 190 | P26: Sofia | Q26: =N26+O26 -> 190
A27: =A26+1 -> 23 | B27: 46024 | C27: 71460870 | D27: Gustavo Enrique Benites Aguilar | E27: gustavo.gba07@hotmail.com | F27: LINCE | G27: 991 714 494 | H27: X | J27: 220 | L27: PAGO | M27: PLIN JL | N27: 220 | P27: Yadhira | Q27: =N27+O27 -> 220
A28: =A27+1 -> 24 | B28: 46024 | C28: 42296972 | D28: Jose Gabriel Janampa Osores | E28: janampaosores@gmail.com | H28: x | J28: 190 | L28: PAGO | M28: PLIN JL | N28: 190 | P28: Katherine | Q28: =N28+O28 -> 190
A29: =A28+1 -> 25 | B29: 46024 | C29: 47162607 | D29: Deessiree Menendez ortiz | E29: deessiree16@hotmail.com | F29: CALLAO | G29: 958 154 071 | H29: X | J29: 175 | K29: 175 | L29: COBR | M29: MERC-PAG | N29: 167.2 | O29: 167.2 | P29: Yadhira | Q29: =N29+O29 -> 334.4
A30: =A29+1 -> 26 | B30: 46024 | C30: 41397674 | D30: Arnaldo Guardamino cavezas | E30: Arn_g2005@hotmail | F30: CALLAO | G30: 958 154 071 | H30: X | J30: 175 | K30: 175 | L30: COBR | M30: MERC-PAG | N30: 167.2 | O30: 167.2 | P30: Yadhira | Q30: =N30+O30 -> 334.4
A31: =A30+1 -> 27 | B31: 46024 | C31: 72413600 | D31: Daniel Ricardo moran Chávez | E31: danielpupunovich5@hotmail.com | G31: 988 766 216 | H31: X | J31: 190 | L31: PAGO | M31: PLIN JL | N31: 190 | P31: Yadhira | Q31: =N31+O31 -> 190
A32: =A31+1 -> 28 | B32: 46024 | D32: Frank Alonso Bautista Cucho | H32: x | J32: 190 | L32: PAGO | M32: PLIN JL | N32: 190 | P32: Katherine | Q32: =N32+O32 -> 190
A33: =A32+1 -> 29 | B33: 46024 | C33: 71523029 | D33: Aaron Castillo | H33: x | J33: 190 | L33: PAGO | M33: YAPE JL | N33: 190 | P33: Katherine | Q33: =N33+O33 -> 190
A34: =A33+1 -> 30 | B34: 46024 | C34: 40697850 | D34: Sergio Armando Lopez Saldaña | E34: Sergio.lsaldana@gmail.com | F34: Victoria | G34: 987 809 308 | H34: x | J34: 190 | L34: PAGO | M34: YAPE JL | N34: 190 | P34: Sofia | Q34: =N34+O34 -> 190
A35: =A34+1 -> 31 | B35: 46024 | C35: 07524459 | D35: José pineda sifuentes | E35: jose.pineda@ae.edu.pe | F35: SAN ISIDRO | G35: 981 398 282 | H35: X | J35: 175 | L35: PAGO | M35: PLIN JL | N35: 175 | P35: Yadhira | Q35: =N35+O35 -> 175
A36: =A35+1 -> 32 | B36: 46024 | D36: Ana Paula Pineda | F36: SAN ISIDRO | H36: X | J36: 100 | L36: PAGO | M36: PLIN JL | N36: 100 | P36: Yadhira | Q36: =N36+O36 -> 100 | R36: MENOR DE 10 AÑOS
A37: =A36+1 -> 33 | B37: 46024 | C37: 42048172 | D37: Luis Esteban Ramos Nicoll | E37: luisramosnicoll@gmail.com | H37: x | J37: 180 | L37: PAGO | M37: BCP JL | N37: 180 | P37: Katherine | Q37: =N37+O37 -> 180
A38: =A37+1 -> 34 | B38: 46025 | C38: 32992113 | D38: Herbert Ricardo Arroyo Vilchez | E38: hricardoarroyov@gmail.com | F38: VES | G38: 976 352 593 | H38: X | J38: 95 | K38: 95 | L38: COBR | M38: PLIN JL | N38: 95 | O38: 95 | P38: Yadhira | Q38: =N38+O38 -> 190
A39: =A38+1 -> 35 | B39: 46025 | C39: 16683079 | D39: Ruth Goyzueta Valencia | E39: rmgvalencia@hotmail.com | F39: La Molina | G39: 965 007 792 | H39: x | J39: 190 | L39: PAGO | M39: YAPE JL | N39: 190 | P39: Sofia | Q39: =N39+O39 -> 190
A40: =A39+1 -> 36 | B40: 46025 | C40: 10116845 | D40: Isabel Cecilia granza toro | F40: EL AGUSTINO | G40: 951 684 925 | H40: X | J40: 220 | L40: PAGO | M40: BCP EPP | N40: 220 | P40: Yadhira | Q40: =N40+O40 -> 220
...

Sheet AFI-F2
A2: CONTROL DE REGISTRO PARTICIPANTES
A3: PARRILLERO AFICIONADO | G3: 45668
A4: ID | B4: FE_ REGISTRO | C4: DNI | D4: NOMBRES Y APELLIDOS | E4: EMAIL | F4: DISTRITO | H4: BB1 | I4: BB2 | J4: MONTO | K4: xCOBRAR | L4: ESTADO | M4: CUENTA | N4: INGRESO | P4: SALDO | Q4: VENDEDOR | R4: TOTAL | S4: OBSERVACION
A5: 1 | B5: 45993 | C5: 47078798 | D5: Anthony Molina Heredia | E5: anthony.molinah@gmail.com | F5: VMT | G5: 968 358 245 | I5: X | J5: 220 | L5: PAGO | M5: YAPE JL | N5: 220 | Q5: Yadhira | R5: =N5+P5 -> 220 | S5: PAGO POR SEPARADO EL 02/12 Y 19/12
A6: =A5+1 -> 2 | B6: 46008 | C6: 44681923 | D6: Rodrigo Bustamante Moquillaza | E6: Roodj88@gmail.com | F6: SURQUILLO | G6: 995 586 556 | I6: X | J6: 200 | K6: 155 | L6: COBR | M6: YAPE JL | N6: 200 | O6: 155 | Q6: Yadhira | R6: =N6+O6 -> 355
A7: =A6+1 -> 3 | B7: 46008 | D7: Philip Wenter Bustamante | E7: Roodj88@gmail.com | F7: SURQUILLO | G7: 995 586 556 | I7: X | J7: 200 | K7: 155 | L7: COBR | M7: YAPE JL | N7: 200 | O7: 155 | Q7: Yadhira | R7: =N7+O7 -> 355
A8: =A7+1 -> 4 | B8: 46008 | C8: 72495808 | D8: Sebastian Matias Prada Fernandez | E8: Matias_pf_21@hotmail.com | F8: LA VICTORIA | G8: 954 532 968 | H8: X | I8: X | J8: 380 | K8: 190 | L8: PAGO | M8: YAPE JL | N8: 190 | O8: 190 | Q8: Yadhira | R8: =N8+O8 -> 380 | S8: CPMPLETO PAGO EL 09/01
A9: =A8+1 -> 5 | B9: 46008 | C9: 09594474 | D9: Jorge Fernandez Huaman | E9: Matias_pf_21@hotmail.com | F9: LA VICTORIA | G9: 954 532 968 | H9: X | J9: 190 | K9: 95 | L9: PAGO | M9: YAPE JL | N9: 95 | O9: 95 | Q9: Yadhira | R9: =N9+O9 -> 190 | S9: CPMPLETO PAGO EL 09/01
A10: =A9+1 -> 6 | B10: 46014 | C10: 44889118 | D10: Miguel Ángel Requiz Alanís | E10: Miguel.requiz10@gmail.com | F10: SJL | G10: 975 575 476 | H10: X | I10: X | J10: 360 | L10: PAGO | M10: BCP EPP | N10: 360 | Q10: Yadhira | R10: =N10+P10 -> 360
A11: =A10+1 -> 7 | B11: 46014 | C11: 43045566 | D11: Carlos Miguel Olivares Pérez | E11: Miguel.requiz10@gmail.com | F11: CHICLAYO | G11: 975 575 476 | H11: X | I11: X | J11: 360 | L11: PAGO | M11: YAPE JL | N11: 360 | Q11: Yadhira | R11: =N11+P11 -> 360
A12: =A11+1 -> 8 | B12: 46011 | D12: Aldo Augusto Di liberto Roldán | E12: aldodilibertoroldan@gmail.com | F12: CHORRILLOS | G12: 991385736 | H12: X | J12: 95 | K12: 95 | L12: PAGO | M12: BCP EPP | N12: 95 | O12: 95 | Q12: Yadhira | R12: =N12+O12 -> 190
A13: =A12+1 -> 9 | B13: 46011 | D13: Yames Vicente di liberto Roldán | E13: aldodilibertoroldan@gmail.com | F13: CHORRILLOS | G13: 991385736 | H13: X | J13: 95 | K13: 95 | L13: PAGO | M13: BCP EPP | N13: 95 | O13: 95 | Q13: Yadhira | R13: =N13+O13 -> 190
A14: =A13+1 -> 10 | B14: 46386 | C14: 72616360 | D14: Enrique Raynor La Torre Alarcón | E14: enriquelta169@gmail.com | F14: SAN BORJA | G14: 966 922 334 | H14: X | I14: X | J14: 380 | L14: PAGO | M14: YAPE JL | N14: 380 | Q14: Greici | R14: =N14+P14 -> 380
A15: =A14+1 -> 11 | B15: 46021 | C15: 49035262 | D15: Rafael Antony Urbina Peña | E15: rafaelurbi24@gmail.com | F15: LOS OLIVOS | G15: 927 235 029 | I15: X | J15: 0 | L15: PAGO | M15: YAPE JL | N15: 0 | Q15: Yadhira | R15: =N15+P15 -> 0 | S15: PAGO 2 CLASES EL 30/12
A16: =A15+1 -> 12 | B16: 46021 | C16: 49032421 | D16: Pierre Neyra | E16: pierre.neyrape@gmail.com | F16: MIRAFLORES | G16: 954 134 851 | H16: X | J16: 190 | L16: PAGO | M16: MERC-PAG | N16: 181.58 | Q16: Yadhira | R16: =N16+P16 -> 181.58
A17: =A16+1 -> 13 | B17: 46021 | C17: 73185937 | D17: Marieta Calderon | E17: marietacristina@hotmail.com | F17: MIRAFLORES | G17: 954 134 851 | H17: X | J17: 190 | L17: PAGO | M17: MERC-PAG | N17: 181.58 | Q17: Yadhira | R17: =N17+P17 -> 181.58
A18: =A17+1 -> 14 | B18: 46014 | D18: Sergio Jesús Casas Arroyo | F18: Villa María del Triunfo | H18: x | J18: 220 | L18: PAGO | M18: YAPE JL | N18: 220 | Q18: Katherine | R18: =N18+P18 -> 220
A19: =A18+1 -> 15 | B19: 46024 | C19: 42296972 | D19: Jose Gabriel Janampa Osores | E19: janampaosores@gmail.com | I19: x | J19: 190 | L19: PAGO | M19: PLIN JL | N19: 190 | Q19: Katherine | R19: =N19+P19 -> 190
A20: =A19+1 -> 16 | B20: 46022 | C20: 70945763 | D20: kevin alarico cieza | E20: kevinalarico@gmail.com | F20: SMP | H20: X | I20: X | J20: 100 | K20: 250 | L20: COBR | M20: PLIN JL | N20: 100 | O20: 0 | Q20: Greici | R20: =N20+P20 -> 100
A21: =A20+1 -> 17 | B21: 46022 | C21: 47628203 | D21: Juan Carlos Bustamante Merino | E21: Juanca.busta.mer09@gmail.com | F21: SMP | H21: X | I21: X | J21: 100 | K21: 250 | L21: COBR | M21: PLIN JL | N21: 100 | O21: 0 | Q21: Greici | R21: =N21+P21 -> 100
A22: =A21+1 -> 18 | B22: 46024 | C22: 72413600 | D22: Daniel Ricardo moran Chávez | E22: danielpupunovich5@hotmail.com | G22: 988 766 216 | I22: X | J22: 190 | L22: PAGO | M22: PLIN JL | N22: 190 | Q22: Yadhira | R22: =N22+P22 -> 190
A23: =A22+1 -> 19 | B23: 46024 | C23: 71523029 | D23: Aaron Castillo | R23: =N23+P23 -> 0
A24: =A23+1 -> 20 | B24: 46024 | C24: 40697850 | D24: Sergio Armando Lopez Saldaña | E24: Sergio.lsaldana@gmail.com | F24: Victoria | G24: 987 809 308 | I24: X | J24: 190 | L24: PAGO | M24: YAPE JL | N24: 190 | Q24: Sofia | R24: =N24+P24 -> 190
A25: =A24+1 -> 21 | B25: 46024 | C25: 07524459 | D25: José pineda sifuentes | E25: jose.pineda@ae.edu.pe | F25: SAN ISIDRO | G25: 981 398 282 | I25: X | J25: 175 | L25: PAGO | M25: PLIN JL | N25: 175 | Q25: Yadhira | R25: =N25+P25 -> 175
A26: =A25+1 -> 22 | B26: 46024 | D26: Ana Paula Pineda | F26: SAN ISIDRO | I26: X | J26: 100 | L26: PAGO | M26: PLIN JL | N26: 100 | Q26: Yadhira | R26: =N26+P26 -> 100 | S26: MENOR DE 10 AÑOS
A27: =A26+1 -> 23 | B27: 46024 | C27: 42048172 | D27: Luis Esteban Ramos Nicoll | E27: luisramosnicoll@gmail.com | I27: x | J27: 180 | L27: PAGO | M27: BCP JL | N27: 180 | Q27: Katherine | R27: =N27+P27 -> 180
A28: =A27+1 -> 24 | B28: 46024 | C28: 08870972 | D28: José Martin Quineche Sánchez | E28: martinj_98@hotmail.com | F28: Callao | G28: 997 126 675 | H28: X | J28: 100 | K28: 100 | L28: COBR | M28: YAPE JL | N28: 100 | O28: 100 | Q28: Tania | R28: =N28+O28 -> 200
A29: =A28+1 -> 25 | B29: 46025 | C29: 45479473 | D29: Deivy wilson rios anco | E29: Wilsonuni@gmail.com | F29: SAN LUIS | G29: 936 613 646 | H29: X | I29: X | J29: 380 | L29: PAGO | M29: MERC-PAG | N29: 363.16 | Q29: Yadhira | R29: =N29+P29 -> 363.16
A30: =A29+1 -> 26 | B30: 46025 | C30: ⁠45526454 | D30: David Guardia Menendez | E30: ⁠guardiamd@gmail.com | F30: SURCO | G30: 987 760 144 | H30: X | J30: 175 | K30: 175 | L30: COBR | M30: MERC-PAG | N30: 167.2 | O30: 167.2 | Q30: Yadhira | R30: =N30+O30 -> 334.4
A31: =A30+1 -> 27 | B31: 46025 | C31: 45786136 | D31: Lourdes Franco Vidal | E31: ⁠guardiamd@gmail.com | F31: SURCO | G31: 987 760 144 | H31: X | J31: 175 | K31: 175 | L31: COBR | M31: MERC-PAG | N31: 167.2 | O31: 167.2 | Q31: Yadhira | R31: =N31+O31 -> 334.4
A32: =A31+1 -> 28 | B32: 46025 | C32: 45592753 | D32: Jorge Araujo | E32: Jorgearaujo13@hotmail.com | I32: x | J32: 220 | L32: PAGO | M32: YAPE JL | N32: 220 | Q32: Katherine | R32: =N32+P32 -> 220
A33: =A32+1 -> 29 | B33: 46027 | C33: 44784709 | D33: José Ernesto Rodríguez Marcelo | F33: breña | H33: x | J33: 200 | L33: PAGO | M33: YAPE JL | N33: 200 | Q33: Katherine | R33: =N33+P33 -> 200
A34: =A33+1 -> 30 | B34: 46027 | D34: María Quiroga | E34: marijo51290@gmail.com | I34: x | J34: 190 | L34: PAGO | M34: YAPE JL | N34: 190 | Q34: Katherine | R34: =N34+P34 -> 190
A35: =A34+1 -> 31 | B35: 46027 | D35: Carlos Gil | E35: marijo51290@gmail.com | I35: x | J35: 190 | L35: PAGO | M35: YAPE JL | N35: 190 | Q35: Katherine | R35: =N35+P35 -> 190
A36: =A35+1 -> 32 | B36: 46027 | D36: Diego Miletich | E36: patriciaarz@yahoo.es | F36: san miguel | I36: x | J36: 95 | K36: 95 | L36: COBR | M36: YAPE JL | N36: 95 | O36: 95 | Q36: Katherine | R36: =N36+O36 -> 190
A37: =A36+1 -> 33 | B37: 46027 | D37: Mirko Miletich | E37: patriciaarz@yahoo.es | F37: san miguel | I37: x | J37: 95 | K37: 95 | L37: COBR | M37: YAPE JL | N37: 95 | O37: 95 | Q37: Katherine | R37: =N37+O37 -> 190
A38: =A37+1 -> 34 | B38: 46026 | C38: 41577290 | D38: Manuel Mori Mideyros | E38: j.chefmori@gmail.com | F38: SAN MARTIN | G38: 945 841 782 | H38: X | I38: X | J38: 380 | L38: PAGO | M38: PLIN JL | N38: 380 | Q38: Yadhira | R38: =N38+P38 -> 380
A39: =A38+1 -> 35 | B39: 46027 | C39: 003012946 | D39: Ambioris Peña | E39: ambiorisellince@gmail.com | F39: SURCO | G39: 940 114 314 | H39: X | I39: X | J39: 380 | L39: PAGO | M39: PLIN JL | N39: 380 | Q39: Yadhira | R39: =N39+P39 -> 380
A40: =A39+1 -> 36 | B40: 46027 | D40: Walter Castro vargas | E40: waltercv2002@hotmail.com | H40: x | I40: x | J40: 330 | K40: 20 | L40: COBR | M40: BCP JL | N40: 330 | O40: 20 | Q40: Katherine | R40: =N40+O40 -> 350
A41: =A40+1 -> 37 | B41: 46027 | D41: Walter Castro Ugarte | E41: waltercv2002@hotmail.com | H41: x | I41: x | J41: 330 | K41: 20 | L41: COBR | M41: BCP JL | N41: 330 | O41: 20 | Q41: Katherine | R41: =N41+O41 -> 350
...

Sheet AFI-F3
A2: CONTROL DE REGISTRO PARTICIPANTES
A3: PARRILLERO AFICIONADO | G3: 45674
A4: ID | B4: FE_ REGISTRO | C4: DNI | D4: NOMBRES Y APELLIDOS | E4: EMAIL | F4: DISTRITO | G4: WSP | H4: BB2 | I4: BB1 | J4: MONTO | K4: xCOBRAR | L4: ESTADO | M4: CUENTA | N4: INGRESO | O4: SALDO | P4: VENDEDOR | Q4: TOTAL | R4: OBSERVACION
A5: 1 | B5: 46014 | C5: 41864072 | D5: Alan Paul Otiniano Azahuanche | E5: apoa315@hotmail.com | F5: SURCO | G5: 949 271 885 | H5: X | J5: 110 | K5: 110 | L5: COBR | M5: YAPE JL | N5: 110 | O5: 110 | P5: Yadhira | Q5: =N5+O5 -> 220 | R5: OBSERVACION
A6: =A5+1 -> 2 | B6: 46014 | C6: 09954438 | D6: Walter Peralta | E6: Carolina.velosa@icloud.com | F6: SAN BORJA | G6: 987 737 748 | I6: X | J6: 220 | L6: PAGO | M6: YAPE JL | N6: 220 | P6: Yadhira | Q6: =N6+O6 -> 220
A7: =A6+1 -> 3 | B7: 46009 | C7: 46649174 | D7: Jonathan Marrou | E7: Jonathan.marrou@gmail.com | F7: SURCO | G7: FB | I7: X | J7: 190 | L7: PAGO | M7: BCP EPP | N7: 190 | P7: Yadhira | Q7: =N7+O7 -> 190
A8: =A7+1 -> 4 | B8: 46009 | C8: 10303242 | D8: Ricardo Marrou | E8: Ricardo.jonico@gmail.com | F8: SURCO | G8: FB | I8: X | J8: 190 | L8: PAGO | M8: BCP EPP | N8: 190 | P8: Yadhira | Q8: =N8+O8 -> 190
A9: =A8+1 -> 5 | B9: 46014 | C9: 44273674 | D9: Ivan Salsavilca Faustino | E9: ivansalsavilca@gmail.com | H9: x | I9: x | J9: 380 | L9: PAGO | M9: YAPE JL | N9: 380 | P9: Katherine | Q9: =N9+O9 -> 380
A10: =A9+1 -> 6 | B10: 46024 | C10: 77059170 | D10: Nicolas Gámez | E10: Nicogamez1008@gmail.com | F10: Chorrillos | G10: 924 714 156 | H10: X | I10: x | J10: 220 | K10: 160 | L10: COBR | M10: PLIN JL | N10: 220 | O10: 160 | P10: Sofia | Q10: =N10+O10 -> 380 | R10: COMPLETARA PAGO 04/01
A11: =A10+1 -> 7 | B11: 46027 | C11: 42126105 | D11: Manuel Buendia | E11: Mbuendia4@gmail.com | F11: CHACLACAYO | G11: 961 082 768 | H11: X | I11: X | J11: 175 | K11: 175 | L11: COBR | M11: BCP EPP | N11: 175 | O11: 175 | P11: Yadhira | Q11: =N11+O11 -> 350
A12: =A11+1 -> 8 | B12: 46027 | C12: 41758472 | D12: Liselle Prieto | E12: Lisibuendia28@gmail.com | F12: CHACLACAYO | G12: 961 082 768 | H12: X | I12: X | J12: 175 | K12: 175 | L12: COBR | M12: BCP EPP | N12: 175 | O12: 175 | P12: Yadhira | Q12: =N12+O12 -> 350
A13: =A12+1 -> 9 | B13: 46006 | C13: 10734077 | D13: Sandro León Anfossi | E13: luciapari87@outlook.com | F13: SURCO | G13: 957 799 157 | H13: X | J13: 0 | N13: 0 | P13: Yadhira | Q13: =N13+O13 -> 0 | R13: REPROGRAMACIÓN
A14: =A13+1 -> 10 | B14: 46028 | C14: 41570562 | D14: Willy rabanal calderon | E14: Rabanalwilly@gmail.com | F14: Callao | G14: 991 049 152 | H14: x | I14: x | J14: 190 | K14: 190 | L14: COBR | M14: BCP JL | N14: 190 | O14: 190 | P14: Gabriela | Q14: =N14+O14 -> 380
A15: =A14+1 -> 11 | B15: 46028 | C15: 48129640 | D15: Bryan Ochoa Salas | E15: bochoa@pucp.pe | F15: Breña | G15: 917 880 991 | H15: x | J15: 175 | L15: PAGO | M15: YAPE JL | N15: 175 | P15: Gabriela | Q15: =N15+O15 -> 175
A16: =A15+1 -> 12 | B16: 46028 | C16: 70605782 | D16: Néstor Walter Villegas Macedo | E16: nestor_vm1994@hotmail.com | F16: Lince | G16: 917 880 991 | H16: x | J16: 175 | L16: PAGO | M16: YAPE JL | N16: 175 | P16: Gabriela | Q16: =N16+O16 -> 175
A17: =A16+1 -> 13 | B17: 46028 | C17: 40298292 | D17: Carlos Cuadra Macedo | E17: carlonchocuadra@gmail.com | F17: Lince | G17: 917 880 991 | H17: x | J17: 175 | L17: PAGO | M17: YAPE JL | N17: 175 | P17: Gabriela | Q17: =N17+O17 -> 175
A18: =A17+1 -> 14 | B18: 46028 | C18: 70437688 | D18: Franco Daniel Delzo Cuyubamba | E18: Delzofranco@gmail.com | F18: San Miguel | G18: 917 880 991 | H18: x | J18: 175 | L18: PAGO | M18: YAPE JL | N18: 175 | P18: Gabriela | Q18: =N18+O18 -> 175
A19: =A18+1 -> 15 | B19: 46027 | C19: 46123466 | D19: Pilar coveñas Ramos | E19: naturaquimi@gmail.com | F19: SMP | G19: 965 713 303 | I19: X | J19: 0 | L19: PAGO | M19: YAPE JL | P19: Yadhira | Q19: =N19+O19 -> 0
A20: =A19+1 -> 16 | B20: 46030 | C20: 46063723 | D20: carlos ore yufre | E20: carlosyufre29@gmail.com | F20: los olivos | G20: 948350215 | H20: x | J20: 190 | K20: 190 | L20: COBR | M20: YAPE JL | N20: 190 | O20: 190 | P20: Sofia | Q20: =N20+O20 -> 380
A21: =A20+1 -> 17 | B21: 46029 | C21: 73563073 | D21: Jesús Amir Huaccho Hidalgo | E21: ruthm_hidalgo@hotmail.com | F21: SURCO | G21: 996 757 353 | I21: X | J21: 190 | L21: PAGO | M21: YAPE JL | N21: 190 | P21: Yadhira | Q21: =N21+O21 -> 190
A22: =A21+1 -> 18 | B22: 46031 | C22: 74743912 | D22: Marco Antonio Escobar Nolazco | E22: escobar010201@gmail.com | F22: VES | G22: 926 468 622 | H22: X | I22: X | J22: 180 | K22: 180 | L22: PAGO | M22: BBVA JL | N22: 180 | O22: 180 | P22: Yadhira | Q22: =N22+O22 -> 360
A23: =A22+1 -> 19 | B23: 46031 | C23: 41552489 | D23: David Sánchez Calle | E23: davsan82@hotmail.com | F23: ATE | G23: 973 110 496 | I23: X | J23: 180 | L23: PAGO | M23: BCP EPP | N23: 180 | P23: Yadhira | Q23: =N23+O23 -> 180
A24: =A23+1 -> 20 | B24: 46031 | C24: 41878729 | D24: Carmen Casana López | E24: crcl83@hotmail.com | F24: ATE | G24: 973 110 496 | I24: X | J24: 180 | L24: PAGO | M24: BCP EPP | N24: 180 | P24: Yadhira | Q24: =N24+O24 -> 180
A25: =A24+1 -> 21 | B25: 46031 | C25: 79820823 | D25: Mariano Sánchez Casana | E25: davsan82@gmail.com | F25: ATE | G25: 973 110 496 | I25: X | J25: 100 | L25: PAGO | M25: BCP EPP | N25: 100 | P25: Yadhira | Q25: =N25+O25 -> 100
A26: =A25+1 -> 22 | B26: 46032 | C26: 40371144 | D26: Pavel N. Paredes Diaz | E26: Pavelpadiaz@gmail.com | F26: Pisco | G26: 969 732 961 | H26: X | I26: X | J26: 380 | L26: PAGO | M26: BCP JL | N26: 380 | P26: Gabriela | Q26: =N26+O26 -> 380
A27: =A26+1 -> 23 | B27: 46030 | C27: 42161125 | D27: Luis Alberto cavero alvites | H27: x | I27: x | J27: 190 | K27: 190 | L27: COBR | M27: YAPE JL | N27: 190 | O27: 190 | P27: Katherine | Q27: =N27+O27 -> 380
A28: =A27+1 -> 24 | B28: 46032 | C28: 23600914 | D28: Edgar Lenin Hernandez Ore | I28: x | J28: 220 | L28: PAGO | M28: YAPE JL | N28: 220 | P28: Katherine | Q28: =N28+O28 -> 220
A29: =A28+1 -> 25 | B29: 46032 | C29: 44204321 | D29: Gustavo Córdova nieto | E29: gustavocordova2015@gmail.com | F29: SJL | G29: 912 909 308 | H29: X | J29: 100 | K29: 100 | L29: PAGO | M29: YAPE JL | N29: 100 | O29: 100 | P29: Yadhira | Q29: =N29+O29 -> 200
A30: =A29+1 -> 26 | B30: 46033 | D30: JOSUE DEL VALLE | H30: X | J30: 0 | L30: PAGO | M30: YAPE JL | N30: 0 | P30: JL | Q30: =N30+O30 -> 0
A31: =A30+1 -> 27 | B31: 46034 | C31: 06967251 | D31: Aldo Viacava Nájera | E31: aldoviacava@msn.com | F31: SAN ISIDRO | G31: 999 207 109 | H31: X | J31: 180 | L31: PAGO | M31: YAPE JL | N31: 180 | P31: Yadhira | Q31: =N31+O31 -> 180
A32: =A31+1 -> 28 | B32: 46034 | C32: 74565573 | D32: Aldo Renzo Viacaa Benavides | E32: aldoviacava00@outlook.com | F32: SAN ISIDRO | G32: 999 207 109 | H32: X | J32: 180 | L32: PAGO | M32: YAPE JL | N32: 180 | P32: Yadhira | Q32: =N32+O32 -> 180
A33: =A32+1 -> 29 | B33: 46034 | C33: 09033925 | D33: EDGAR PANDURO | E33: ELPY1967@GMAIL.COM | F33: CAÑETE | G33: 943 368 377 | I33: X | J33: 100 | K33: 100 | L33: COBR | M33: YAPE JL | N33: 100 | O33: 100 | P33: Greici | Q33: =N33+O33 -> 200
A34: =A33+1 -> 30 | B34: 46034 | C34: 70342491 | D34: Jandir Rivera Quispe | E34: jandir.rivera10@gmail.com | F34: San Bartolo | G34: 987552563 | H34: X | J34: 180 | K34: 180 | L34: COBR | M34: MERC-PAG | N34: 180 | O34: 165 | P34: Sofia | Q34: =N34+O34 -> 345
A35: =A34+1 -> 31 | B35: 46034 | C35: 74711615 | D35: Edu Escobedo Yalico | H35: x | I35: x | J35: 350 | L35: PAGO | M35: YAPE JL | N35: 350 | P35: Katherine | Q35: =N35+O35 -> 350
A36: =A35+1 -> 32 | B36: 46034 | D36: Fernanda Yalico Canchari | H36: x | I36: x | J36: 350 | L36: PAGO | M36: YAPE JL | N36: 350 | P36: Katherine | Q36: =N36+O36 -> 350
A37: =A36+1 -> 33 | B37: 46032 | D37: Nico Suárez Loayza | H37: x | I37: x | J37: 200 | K37: 180 | L37: COBR | M37: YAPE JL | N37: 200 | O37: 180 | P37: Katherine | Q37: =N37+O37 -> 380
A38: =A37+1 -> 34 | N38: 0 | P38: Greici | Q38: =N38+O38 -> 0
A39: =A38+1 -> 35 | B39: 46034 | C39: 48194840 | D39: Fritz puente | E39: fritz_jairo@hotmail .com | F39: Los olivos | G39: 966 505 141 | H39: X | J39: 100 | K39: 100 | L39: COBR | M39: YAPE JL | N39: 100 | O39: 100 | P39: Sofia | Q39: =N39+O39 -> 200
A40: =A39+1 -> 36 | B40: 46024 | D40: Aaron Castillo | I40: x | J40: 190 | L40: PAGO | M40: YAPE JL | N40: 190 | P40: Katherine | Q40: =N40+O40 -> 190
A41: =A40+1 -> 37 | B41: 46024 | D41: Aaron Castillo | I41: x | J41: 190 | L41: PAGO | M41: YAPE JL | N41: 190 | P41: Katherine | Q41: =N41+O41 -> 190
...

Sheet AFI-F4
A2: CONTROL DE REGISTRO PARTICIPANTES
A3: PARRILLERO AFICIONADO | G3: 45682
A4: ID | B4: FE_ REGISTRO | C4: DNI | D4: NOMBRES Y APELLIDOS | E4: EMAIL | F4: DISTRITO | G4: WSP | H4: BB1 | I4: BB2 | J4: MONTO | K4: xCOBRAR | L4: ESTADO | M4: CUENTA | N4: INGRESO | O4: SALDO | P4: VENDEDOR | Q4: TOTAL | R4: OBSERVACION
A5: 1 | B5: 46000 | C5: 44412013 | D5: Nazaret judith abad zarco | E5: Nazaret_abad@hotmail.com | F5: SAN MIGUEL | G5: 976 096 059 | H5: X | J5: 190 | L5: PAGO | M5: YAPE JL | N5: 190 | P5: Yadhira | Q5: =N5+O5 -> 190 | R5: OBSERVACION
A6: =A5+1 -> 2 | B6: 46000 | C6: 10562497 | D6: Rubén Abad Zarco | E6: Nazaret_abad@hotmail.com | F6: SAN MIGUEL | G6: 976 096 059 | H6: X | J6: 190 | L6: PAGO | M6: YAPE JL | N6: 190 | P6: Yadhira | Q6: =N6+O6 -> 190
A7: =A6+1 -> 3 | B7: 46024 | C7: 76197577 | D7: Anderson Achata | E7: andersonachata@gmail.com | F7: SAN LUIS | G7: 913 872 010 | H7: X | J7: 190 | L7: PAGO | M7: PLIN JL | N7: 190 | P7: Yadhira | Q7: =N7+O7 -> 190
A8: =A7+1 -> 4 | B8: 46025 | C8: 41735143 | D8: Danilo Fernando Yánac Talaverano | E8: Dyanact@gmail.com | F8: LOS OLIVOS | G8: 949 727 949 | H8: X | J8: 110 | K8: 270 | L8: COBR | M8: PLIN JL | N8: 110 | O8: 0 | P8: Yadhira | Q8: =N8+O8 -> 110
A9: =A8+1 -> 5 | B9: 46018 | C9: 40893521 | D9: Rolando Farfán Gutiérrez | E9: Rolandofarfang@gmail.com | F9: CERCADO | G9: 999 143 296 | I9: X | J9: 175 | L9: PAGO | M9: PLIN JL | N9: 175 | P9: Greici | Q9: =N9+O9 -> 175 | R9: validado en diciembre, costo reprogramacion
A10: =A9+1 -> 6 | N10: 0 | P10: Sofia | Q10: =N10+O10 -> 0
A11: =A10+1 -> 7 | B11: 46028 | C11: 44384611 | D11: LUIGGI VIGO PESANTES | E11: luiggijvp@gmail.com | F11: PUEBLO LIBRE | I11: X | J11: 100 | K11: 100 | L11: COBR | M11: YAPE JL | N11: 100 | O11: 100 | P11: Greici | Q11: =N11+O11 -> 200
A12: =A11+1 -> 8 | B12: 46031 | C12: 6800803 | D12: Jorge Aguinaga Alvites | E12: jorge.aguinaga@gmail.com | F12: San miguel | G12: 961377923 | I12: x | J12: 220 | L12: PAGO | M12: YAPE JL | N12: 220 | P12: Gabriela | Q12: =N12+O12 -> 220
A13: =A12+1 -> 9 | B13: 46034 | C13: 70342491 | D13: Jandir Rivera Quispe | E13: jandir.rivera10@gmail.com | F13: San Bartolo | G13: 987552563 | H13: X | J13: 0 | N13: 0 | P13: Sofia | Q13: =N13+O13 -> 0 | R13: cobrar 17
A14: =A13+1 -> 10 | M14: YAPE JL | N14: 0 | P14: Yadhira | Q14: =N14+O14 -> 0 | R14: CANCELO EN SU BB1 EL 11/01
A15: =A14+1 -> 11 | M15: YAPE JL | N15: 0 | P15: Yadhira | Q15: =N15+O15 -> 0 | R15: CANCELO EN SU BB1 EL 11/01
A16: =A15+1 -> 12 | B16: 46034 | C16: 40493159 | D16: Manuel Grados Morales | E16: manuel.grados.gm@gmail.com | F16: SAN ISIDRO | G16: 954 580 454 | H16: X | J16: 190 | L16: PAGO | M16: YAPE JL | N16: 190 | P16: Greici | Q16: =N16+O16 -> 190
A17: =A16+1 -> 13 | B17: 46034 | C17: 45909459 | D17: Jonathan Ramírez Flor | E17: joramirezf@hotmail.com | F17: JESUS MARIA | G17: 954 580 454 | H17: X | J17: 190 | L17: PAGO | M17: YAPE JL | N17: 190 | P17: Greici | Q17: =N17+O17 -> 190
A18: =A17+1 -> 14 | B18: 46035 | C18: 47575960 | D18: Abdul Kazan Espinoza Guerra | E18: Ka.carmed@gmail.com | F18: RIMAC | G18: 970 345 673 | H18: X | J18: 190 | L18: PAGO | M18: YAPE JL | N18: 190 | P18: Yadhira | Q18: =N18+O18 -> 190
A19: =A18+1 -> 15 | B19: 46035 | C19: 15753576 | D19: Jaime Raúl Santa Cruz Culquicondor | E19: Jaimesantacruz2306@gmail.com | F19: HUARAL | G19: 998 341 966 | H19: X | I19: X | J19: 180 | K19: 180 | L19: COBR | M19: BBVA JL | N19: 180 | O19: 180 | P19: Yadhira | Q19: =N19+O19 -> 360
A20: =A19+1 -> 16 | B20: 46036 | C20: 10114558 | D20: Ricardo Francisco Florian | E20: francisco.rm@pucp.pe | F20: SJL | G20: 986 601 138 | H20: X | J20: 90 | K20: 90 | L20: COBR | M20: YAPE JL | N20: 90 | O20: 90 | P20: Yadhira | Q20: =N20+O20 -> 180
A21: =A20+1 -> 17 | B21: 46036 | C21: 75527342 | D21: Manuel Francisco Davalos | E21: francisco.rm@pucp.pe | F21: SJL | G21: 986 601 138 | H21: X | J21: 90 | K21: 90 | L21: COBR | M21: YAPE JL | N21: 90 | O21: 90 | P21: Yadhira | Q21: =N21+O21 -> 180
A22: =A21+1 -> 18 | B22: 46035 | C22: 42084574 | D22: Cesar La Rosa-Sánchez Cordero | E22: cesarlarosa_20@yahoo.com.pe | H22: x | I22: x | J22: 380 | L22: PAGO | M22: YAPE JL | N22: 380 | P22: Katherine | Q22: =N22+O22 -> 380
A23: =A22+1 -> 19 | B23: 46036 | C23: 61802066 | D23: Alexander Zambrano Vizcarra | F23: San Juan de Miraflores | H23: x | J23: 190 | L23: PAGO | M23: YAPE JL | N23: 190 | P23: Katherine | Q23: =N23+O23 -> 190
A24: =A23+1 -> 20 | B24: 46036 | C24: 61741943 | D24: Fabricio Urbina Zambrano | F24: San Juan de Miraflores | H24: x | J24: 190 | L24: PAGO | M24: YAPE JL | N24: 190 | P24: Katherine | Q24: =N24+O24 -> 190
A25: =A24+1 -> 21 | B25: 46036 | C25: 70919834 | D25: Carlos Eduardo Cumpa alayo | F25: San Juan de lurigancho | H25: x | J25: 200 | L25: PAGO | M25: YAPE JL | N25: 200 | P25: Katherine | Q25: =N25+O25 -> 200
A26: =A25+1 -> 22 | B26: 46036 | C26: 25728595 | D26: Juan Augusto Arrunátegui Paiva | E26: arrunateguijuan@gmail.com | F26: Pueblo Libre | H26: x | J26: 190 | L26: PAGO | N26: 190 | P26: Gabriela | Q26: =N26+O26 -> 190
A27: =A26+1 -> 23 | B27: 46036 | C27: 73171842 | D27: César Augusto Arrunátegui Vásquez | E27: arrunateguijuan@gmail.com | F27: Pueblo libre | H27: x | I27: x | J27: 110 | K27: 270 | L27: PAGO | N27: 110 | O27: 270 | P27: Gabriela | Q27: =N27+O27 -> 380
A28: =A27+1 -> 24 | B28: 46036 | C28: 76601657 | D28: Anthony Giancarlos rios agesto | E28: gian.agesto.tkm@gmail.com | F28: Huacho | H28: x | J28: 150 | L28: PAGO | N28: 150 | P28: Gabriela | Q28: =N28+O28 -> 150
A29: =A28+1 -> 25 | B29: 46036 | C29: 40902213 | D29: DAVID DANIEL ECOS BENAVIDES | E29: david.ecos@icloud.com | F29: Lince | G29: 923 335 713 | H29: x | I29: x | J29: 380 | L29: PAGO | M29: BCP JL | N29: 150 | P29: Gabriela | Q29: =N29+O29 -> 150
A30: =A29+1 -> 26 | B30: 46037 | C30: 77060706 | D30: ALEXIS FABIAN SANTA CRUZ QUILLAY | E30: santacruzalexis950@gmail.com | F30: HUARAL | G30: 917395017 | H30: X | I30: X | J30: 180 | K30: 180 | L30: COBR | M30: BBVA JL | N30: 180 | O30: 180 | P30: Yadhira | Q30: =N30+O30 -> 360
A31: =A30+1 -> 27 | B31: 46038 | C31: *09493577 | D31: MARCO DEL CASTILLO RUIZ CARO | E31: MMDCRC@HOTMAIL.COM | F31: Chorrillos | H31: x | I31: x | J31: 380 | L31: PAGO | M31: YAPE JL | N31: 380 | P31: Gabriela | Q31: =N31+O31 -> 380
A32: =A31+1 -> 28 | B32: 46038 | C32: 76799413 | D32: Gerson Alejandro Nogueyra Saldarriaga | E32: ng.producciones.art@gmail.com | F32: CALLAO | G32: 923 677 984 | H32: X | J32: 0 | N32: 0 | P32: Yadhira | Q32: =N32+O32 -> 0 | R32: PAGARA EN CLASE DE CYC 18/01
A33: =A32+1 -> 29 | B33: 46038 | C33: 45963559 | D33: ROSARIO TRUJILLO HIGINIO | H33: x | J33: 180 | L33: PAGO | M33: YAPE JL | N33: 180 | P33: Katherine | Q33: =N33+O33 -> 180
A34: =A33+1 -> 30 | B34: 46038 | C34: 42243221 | D34: ALFREDO LOZADA FERNANDEZ | H34: x | J34: 180 | L34: PAGO | M34: YAPE JL | N34: 180 | P34: Katherine | Q34: =N34+O34 -> 180
A35: =A34+1 -> 31 | B35: 46038 | C35: 7576311 | D35: Carlos sucasaca Vargas | E35: Carlossucasaca@gmail.com | F35: san Juan de Miraflores | G35: (347) 592-6379 | H35: x | J35: 175 | K35: 45 | L35: COBR | M35: LINK-CULQUI | N35: 166 | O35: 0 | P35: Sofia | Q35: =N35+O35 -> 166 | R35: CANCELO 50 DOLARES
A36: =A35+1 -> 32 | B36: 46038 | D36: Jonathan Ivan Espinoza Ruiz | H36: x | J36: 110 | K36: 110 | L36: COBR | M36: YAPE JL | N36: 110 | O36: 110 | P36: Katherine | Q36: =N36+O36 -> 220
A37: =A36+1 -> 33 | B37: 46038 | C37: 43567257 | D37: Marleny Quispe Vilca | H37: x | I37: x | J37: 200 | K37: 180 | L37: COBR | M37: YAPE JL | N37: 200 | O37: 180 | P37: Gabriela | Q37: =N37+O37 -> 380
A38: =A37+1 -> 34 | B38: 46038 | C38: *005367250 | D38: Andres valencia muñoz | E38: Kevinandresvalenciamunoz@gmail.com | F38: La Molina | I38: x | J38: 190 | K38: 190 | L38: COBR | M38: YAPE JL | N38: 190 | O38: 190 | P38: Gabriela | Q38: =N38+O38 -> 380
A39: =A38+1 -> 35 | B39: 46039 | C39: 10624546 | D39: Carlos Zuñiga Cabrera | E39: carlosazunigacabrera@gmail.com | F39: Jesus Maria | G39: 964 850 682 | H39: x | J39: 200 | L39: PAGO | M39: YAPE JL | N39: 200 | P39: Sofia | Q39: =N39+O39 -> 200
A40: =A39+1 -> 36 | B40: 46039 | C40: 06532689, | D40: Mack Alexis Flores Chalco, | E40: alexisflores1973@gmail.com | F40: Miraflores, | I40: x | J40: 100 | K40: 100 | L40: COBR | M40: YAPE JL | N40: 100 | O40: 100 | P40: Sofia | Q40: =N40+O40 -> 200 | R40: pago 50%
A41: =A40+1 -> 37 | B41: 46041 | C41: 45083846 | D41: Jheff Alfredo Laura Martínez | E41: simplementejheff@gmail.com | F41: SURQUILLO | G41: 954 088 624 | H41: X | J41: 95 | K41: 95 | L41: COBR | M41: YAPE JL | N41: 95 | O41: 95 | P41: Yadhira | Q41: =N41+O41 -> 190
...

Sheet AFI-F5
A1: - | D1: J
A2: CONTROL DE REGISTRO PARTICIPANTES
A3: PARRILLERO AFICIONADO | G3: 45688
A4: ID | B4: FE_ REGISTRO | C4: DNI | D4: NOMBRES Y APELLIDOS | E4: EMAIL | F4: DISTRITO | G4: WSP | H4: BB2 | I4: BB1 | J4: MONTO | K4: xCOBRAR | L4: ESTADO | M4: CUENTA | N4: INGRESO | O4: SALDO | P4: VENDEDOR | Q4: TOTAL | R4: OBSERVACION
A5: 1 | B5: 46024 | C5: 76197577 | D5: Anderson Achata | E5: andersonachata@gmail.com | F5: SAN LUIS | G5: 913 872 010 | H5: X | J5: 190 | L5: PAGO | M5: PLIN JL | N5: 190 | P5: Yadhira | Q5: =N5+O5 -> 190 | R5: OBSERVACION
A6: =A5+1 -> 2 | B6: 46025 | C6: 41735143 | D6: Danilo Fernando Yánac Talaverano | E6: Dyanact@gmail.com | F6: LOS OLIVOS | G6: 949 727 949 | H6: X | J6: 0 | N6: 0 | P6: Yadhira | Q6: =N6+O6 -> 0 | R6: PAGARA EN SU CLASE 25/01
A7: =A6+1 -> 3 | B7: 46038 | C7: *005367250 | D7: Andres valencia muñoz | E7: Kevinandresvalenciamunoz@gmail.com | F7: La Molina | I7: x | J7: 0 | N7: 0 | P7: Yadhira | Q7: =N7+O7 -> 0
A8: =A7+1 -> 4 | B8: 46042 | C8: 72751542 | D8: Esteban Camarena Seminario | E8: esteban.camarena.stevejobs@gmail.com | Q8: =N8+O8 -> 0 | R8: reprogramo para el 07/02
A9: =A8+1 -> 5 | B9: 46030 | C9: 46063723 | D9: carlos ore yufre | E9: carlosyufre29@gmail.com | F9: los olivos | G9: 948350215 | I9: X | J9: 0 | L9: PAGO | N9: 0 | P9: Sofia | Q9: =N9+O9 -> 0 | R9: PAGO EL 17
A10: =A9+1 -> 6 | B10: 46042 | C10: 20063027 | D10: Irene Delma Calderón Marcos | E10: irene_delma11@hotmail.com | F10: CERCADO | G10: 982 593 099 | H10: X | J10: 190 | K10: 190 | L10: COBR | M10: YAPE JL | N10: 190 | O10: 190 | P10: Greici | Q10: =N10+O10 -> 380 | R10: LLEVARA 2 CURSOS, COBRAR LO RESTANTE
A11: =A10+1 -> 7 | B11: 46042 | C11: 41455446 | D11: Eder Genaro Estrada Montañez | E11: eder16221@gmail.com | F11: Callao | G11: =51977709418 -> 51977709418 | I11: x | J11: 190 | K11: 0 | L11: PAGO | N11: 190 | P11: Sofia | Q11: =N11+O11 -> 190 | R11: ya pago x 2 clases
A12: =A11+1 -> 8 | B12: 46042 | C12: 44211612 | D12: Victor Caballero | E12: victorcaballeror@gmail.com | F12: san Borja | G12: =51944252125 -> 51944252125 | I12: x | J12: 0 | K12: 0 | N12: 0 | P12: Yadhira | Q12: =N12+O12 -> 0 | R12: pagara el 25
A13: =A12+1 -> 9 | B13: 46043 | C13: 10117893 | D13: Juan Valencia León | E13: jvl.juanvalencialeon@gmail.com | F13: SJL | G13: 962 075 283 | I13: x | J13: 210 | L13: PAGO | M13: LINK-CULQUI | N13: 195 | P13: Sofia | Q13: =N13+O13 -> 195
A14: =A13+1 -> 10 | B14: 46045 | C14: 6189524 | D14: Raul plácido Villavicencio torre | E14: rpvillavicencio@hotmail.com | F14: La Molina | G14: 948 310 299 | I14: X | J14: 175 | K14: 175 | L14: COBR | M14: PLIN JL | N14: 175 | O14: 175 | P14: Sofia | Q14: =N14+O14 -> 350
A15: =A14+1 -> 11 | B15: 46045 | C15: 72903045 | D15: Raul Ricardo Villavicencio Cabrera | F15: La Molina | G15: 948 310 299 | I15: X | J15: 175 | K15: 175 | L15: COBR | M15: PLIN JL | N15: 175 | O15: 175 | P15: Sofia | Q15: =N15+O15 -> 350
A16: =A15+1 -> 12 | B16: 46044 | C16: 20538382598 | D16: César Domínguez Añanca | E16: serfafain.sac@hotmail.com | F16: Callao | G16: =+51998294866 -> 51998294866 | I16: X | J16: 100 | K16: 100 | L16: COBR | M16: YAPE JL | N16: 100 | O16: 100 | P16: Sofia | Q16: =N16+O16 -> 200
A17: =A16+1 -> 13 | N17: 180 | P17: Sofia | Q17: =N17+O17 -> 180 | R17: reprogramacion 28 febrero
A18: =A17+1 -> 14 | B18: 46045 | C18: 44767965 | D18: Massiel Karolina Ayala Guerra | I18: x | L18: PAGO | N18: 0 | P18: Katherine | Q18: =N18+O18 -> 0
A19: =A18+1 -> 15 | B19: 46046 | C19: 41855242 | D19: Jimmy Joel lizarzaburu martel | E19: Jimmijoel123@hotmail.com | F19: Huacho | G19: 934091909 | H19: X | I19: X | J19: 200 | K19: 150 | L19: COBR | M19: BBVA JL | N19: 200 | O19: 150 | P19: Sofia | Q19: =N19+O19 -> 350
A20: =A19+1 -> 16 | B20: 46047 | C20: 40 767009 | D20: Angela Geraldine quiñones granados | E20: Jimmijoel123@hotmail.com | F20: Huacho | G20: 934091909 | H20: X | I20: X | J20: 200 | K20: 150 | L20: COBR | M20: BBVA JL | N20: 200 | O20: 150 | P20: Sofia | Q20: =N20+O20 -> 350
